<?xml version="1.0"?>
<robot name="ur10e_robot">
  <link name="root_link" />

  <link name="virtual_base_link_0" />
  <link name="virtual_base_link_1" />
  <link name="virtual_base_link_2" />
  <joint name="virtual_base_joint_0" type="prismatic">
    <parent link="root_link" />
    <child link="virtual_base_link_0" />
    <origin rpy="0 0 0" xyz="0 0 0" />
    <axis xyz="1 0 0" />
    <limit lower="-3.0" upper="3.0" effort="100.0" velocity="0.0" />
  </joint>
  <joint name="virtual_base_joint_1" type="prismatic">
    <parent link="virtual_base_link_0" />
    <child link="virtual_base_link_1" />
    <origin rpy="0 0 0" xyz="0 0 0" />
    <axis xyz="0 1 0" />
    <limit lower="-3.0" upper="3.0" effort="100.0" velocity="0.0" />
  </joint>
  <joint name="virtual_base_joint_2" type="revolute">
    <parent link="virtual_base_link_1" />
    <child link="virtual_base_link_2" />
    <origin rpy="0 0 0" xyz="0 0 0" />
    <axis xyz="0 0 1" />
    <limit lower="-3.14" upper="3.14" effort="100.0" velocity="0.0" />
  </joint>

  <joint name="root_fixed" type="fixed">
    <origin rpy="0 0 0" xyz="0 0 0" />
    <parent link="virtual_base_link_2" />
    <child link="base_link" />
  </joint>

  <link name="base_link" />
  <link name="base_link_inertia">
    <visual>
      <origin rpy="0 0 3.141592653589793" xyz="0 0 0" />
      <geometry>
        <mesh filename="meshes/visual/base.dae" />
      </geometry>
      <material name="LightGrey">
        <color rgba="0.7 0.7 0.7 1.0" />
      </material>
    </visual>
    <collision>
      <origin rpy="0 0 3.141592653589793" xyz="0 0 0" />
      <geometry>
        <mesh filename="meshes/collision/base.stl" />
      </geometry>
    </collision>
    <inertial>
      <mass value="4.0" />
      <origin rpy="0 0 0" xyz="0 0 0" />
      <inertia ixx="0.0061063308908" ixy="0.0" ixz="0.0" iyy="0.0061063308908" iyz="0.0"
        izz="0.01125" />
    </inertial>
  </link>
  <link name="shoulder_link">
    <visual>
      <origin rpy="0 0 3.141592653589793" xyz="0 0 0" />
      <geometry>
        <mesh filename="meshes/visual/shoulder.dae" />
      </geometry>
      <material name="LightGrey">
        <color rgba="0.7 0.7 0.7 1.0" />
      </material>
    </visual>
    <collision>
      <origin rpy="0 0 3.141592653589793" xyz="0 0 0" />
      <geometry>
        <mesh filename="meshes/collision/shoulder.stl" />
      </geometry>
    </collision>
    <inertial>
      <mass value="7.778" />
      <origin rpy="0 0 0" xyz="0 0 0" />
      <inertia ixx="0.03147431257693659" ixy="0.0" ixz="0.0" iyy="0.03147431257693659" iyz="0.0"
        izz="0.021875624999999996" />
    </inertial>
  </link>
  <link name="upper_arm_link">
    <visual>
      <origin rpy="1.5707963267948966 0 -1.5707963267948966" xyz="0 0 0.1762" />
      <geometry>
        <mesh filename="meshes/visual/upperarm.dae" />
      </geometry>
      <material name="LightGrey">
        <color rgba="0.7 0.7 0.7 1.0" />
      </material>
    </visual>
    <collision>
      <origin rpy="1.5707963267948966 0 -1.5707963267948966" xyz="0 0 0.1762" />
      <geometry>
        <mesh filename="meshes/collision/upperarm.stl" />
      </geometry>
    </collision>
    <inertial>
      <mass value="12.93" />
      <origin rpy="0 1.5707963267948966 0" xyz="-0.306 0.0 0.175" />
      <inertia ixx="0.42175380379841093" ixy="0.0" ixz="0.0" iyy="0.42175380379841093" iyz="0.0"
        izz="0.03636562499999999" />
    </inertial>
  </link>
  <link name="forearm_link">
    <visual>
      <origin rpy="1.5707963267948966 0 -1.5707963267948966" xyz="0 0 0.0393" />
      <geometry>
        <mesh filename="meshes/visual/forearm.dae" />
      </geometry>
      <material name="LightGrey">
        <color rgba="0.7 0.7 0.7 1.0" />
      </material>
    </visual>
    <collision>
      <origin rpy="1.5707963267948966 0 -1.5707963267948966" xyz="0 0 0.0393" />
      <geometry>
        <mesh filename="meshes/collision/forearm.stl" />
      </geometry>
    </collision>
    <inertial>
      <mass value="3.87" />
      <origin rpy="0 1.5707963267948966 0" xyz="-0.285775 0.0 0.0393" />
      <inertia ixx="0.11079302548902206" ixy="0.0" ixz="0.0" iyy="0.11079302548902206" iyz="0.0"
        izz="0.010884375" />
    </inertial>
  </link>
  <link name="wrist_1_link">
    <visual>
      <origin rpy="1.5707963267948966 0 0" xyz="0 0 -0.135" />
      <geometry>
        <mesh filename="meshes/visual/wrist1.dae" />
      </geometry>
      <material name="LightGrey">
        <color rgba="0.7 0.7 0.7 1.0" />
      </material>
    </visual>
    <collision>
      <origin rpy="1.5707963267948966 0 0" xyz="0 0 -0.135" />
      <geometry>
        <mesh filename="meshes/collision/wrist1.stl" />
      </geometry>
    </collision>
    <inertial>
      <mass value="1.96" />
      <origin rpy="0 0 0" xyz="0 0 0" />
      <inertia ixx="0.005108247956699999" ixy="0.0" ixz="0.0" iyy="0.005108247956699999" iyz="0.0"
        izz="0.005512499999999999" />
    </inertial>
  </link>
  <link name="wrist_2_link">
    <visual>
      <origin rpy="0 0 0" xyz="0 0 -0.12" />
      <geometry>
        <mesh filename="meshes/visual/wrist2.dae" />
      </geometry>
      <material name="LightGrey">
        <color rgba="0.7 0.7 0.7 1.0" />
      </material>
    </visual>
    <collision>
      <origin rpy="0 0 0" xyz="0 0 -0.12" />
      <geometry>
        <mesh filename="meshes/collision/wrist2.stl" />
      </geometry>
    </collision>
    <inertial>
      <mass value="1.96" />
      <origin rpy="0 0 0" xyz="0 0 0" />
      <inertia ixx="0.005108247956699999" ixy="0.0" ixz="0.0" iyy="0.005108247956699999" iyz="0.0"
        izz="0.005512499999999999" />
    </inertial>
  </link>
  <link name="wrist_3_link">
    <visual>
      <origin rpy="1.5707963267948966 0 0" xyz="0 0 -0.1168" />
      <geometry>
        <mesh filename="meshes/visual/wrist3.dae" />
      </geometry>
      <material name="LightGrey">
        <color rgba="0.7 0.7 0.7 1.0" />
      </material>
    </visual>
    <collision>
      <origin rpy="1.5707963267948966 0 0" xyz="0 0 -0.1168" />
      <geometry>
        <mesh filename="meshes/collision/wrist3.stl" />
      </geometry>
    </collision>
    <inertial>
      <mass value="0.202" />
      <origin rpy="0 0 0" xyz="0.0 0.0 -0.025" />
      <inertia ixx="0.00014434577559500002" ixy="0.0" ixz="0.0" iyy="0.00014434577559500002"
        iyz="0.0" izz="0.00020452500000000002" />
    </inertial>
  </link>
  <link name="flange" />
  <joint name="base_link-base_link_inertia" type="fixed">
    <parent link="base_link" />
    <child link="base_link_inertia" />
    <origin rpy="0 0 3.141592653589793" xyz="0 0 0" />
  </joint>
  <joint name="shoulder_pan_joint" type="revolute">
    <parent link="base_link_inertia" />
    <child link="shoulder_link" />
    <origin rpy="0 0 0" xyz="0 0 0.1807" />
    <axis xyz="0 0 1" />
    <limit effort="330.0" lower="-6.283185307179586" upper="6.283185307179586"
      velocity="2.0943951023931953" />
    <dynamics damping="0" friction="0" />
  </joint>
  <joint name="shoulder_lift_joint" type="revolute">
    <parent link="shoulder_link" />
    <child link="upper_arm_link" />
    <origin rpy="1.570796327 0 0" xyz="0 0 0" />
    <axis xyz="0 0 1" />
    <limit effort="330.0" lower="-6.283185307179586" upper="6.283185307179586"
      velocity="2.0943951023931953" />
    <dynamics damping="0" friction="0" />
  </joint>
  <joint name="elbow_joint" type="revolute">
    <parent link="upper_arm_link" />
    <child link="forearm_link" />
    <origin rpy="0 0 0" xyz="-0.6127 0 0" />
    <axis xyz="0 0 1" />
    <limit effort="150.0" lower="-3.141592653589793" upper="3.141592653589793"
      velocity="3.141592653589793" />
    <dynamics damping="0" friction="0" />
  </joint>
  <joint name="wrist_1_joint" type="revolute">
    <parent link="forearm_link" />
    <child link="wrist_1_link" />
    <origin rpy="0 0 0" xyz="-0.57155 0 0.17415" />
    <axis xyz="0 0 1" />
    <limit effort="56.0" lower="-6.283185307179586" upper="6.283185307179586"
      velocity="3.141592653589793" />
    <dynamics damping="0" friction="0" />
  </joint>
  <joint name="wrist_2_joint" type="revolute">
    <parent link="wrist_1_link" />
    <child link="wrist_2_link" />
    <origin rpy="1.570796327 0 0" xyz="0 -0.11985 -2.458164590756244e-11" />
    <axis xyz="0 0 1" />
    <limit effort="56.0" lower="-6.283185307179586" upper="6.283185307179586"
      velocity="3.141592653589793" />
    <dynamics damping="0" friction="0" />
  </joint>
  <joint name="wrist_3_joint" type="revolute">
    <parent link="wrist_2_link" />
    <child link="wrist_3_link" />
    <origin rpy="1.570796326589793 3.141592653589793 3.141592653589793"
      xyz="0 0.11655 -2.390480459346185e-11" />
    <axis xyz="0 0 1" />
    <limit effort="56.0" lower="-6.283185307179586" upper="6.283185307179586"
      velocity="3.141592653589793" />
    <dynamics damping="0" friction="0" />
  </joint>
  <joint name="wrist_3-flange" type="fixed">
    <parent link="wrist_3_link" />
    <child link="flange" />
    <origin rpy="0 -1.5707963267948966 -1.5707963267948966" xyz="0 0 0" />
  </joint>

  <link name="tool0" />

  <joint name="flange-tool0" type="fixed">
    <origin rpy="1.5707963267948966 0 1.5707963267948966" xyz="0 0 0" />
    <parent link="flange" />
    <child link="tool0" />
  </joint>
</robot>